# Needed a script to quickly check some webservers

```python
#!/usr/bin/env python3
# -*- coding: utf-8 -*-
# Check webservers
import urllib.request

WWWPORT='9088'
WWWLIST='servers.txt'  # server/IP one per line
TIMEOUT=2

servers2Check = open(WWWLIST, 'r')

for server in servers2Check:
	WWW = str('https://' + server.strip() + ':' + WWWPORT)
	try:
		CODE = urllib.request.urlopen(WWW,None,TIMEOUT).getcode()
		print(str(CODE) + ':' + WWW )
	except urllib.error.URLError:
		print("Timeout:" + WWW + " HOST DOWN!!!!!!!!!!!!!!!!")

```
I added the try/except to account for servers that could be down.  Without the try/except code you would receive this error and the script would bomb.
```
Traceback (most recent call last):
  File "C:\Users\raresteak\AppData\Local\Programs\Python\Python36-32\lib\urllib\request.py", line 1318, in do_open
    encode_chunked=req.has_header('Transfer-encoding'))
  File "C:\Users\raresteak\AppData\Local\Programs\Python\Python36-32\lib\http\client.py", line 1239, in request
    self._send_request(method, url, body, headers, encode_chunked)
  File "C:\Users\raresteak\AppData\Local\Programs\Python\Python36-32\lib\http\client.py", line 1285, in _send_request
    self.endheaders(body, encode_chunked=encode_chunked)
  File "C:\Users\raresteak\AppData\Local\Programs\Python\Python36-32\lib\http\client.py", line 1234, in endheaders
    self._send_output(message_body, encode_chunked=encode_chunked)
  File "C:\Users\raresteak\AppData\Local\Programs\Python\Python36-32\lib\http\client.py", line 1026, in _send_output
    self.send(msg)
  File "C:\Users\raresteak\AppData\Local\Programs\Python\Python36-32\lib\http\client.py", line 964, in send
    self.connect()
  File "C:\Users\raresteak\AppData\Local\Programs\Python\Python36-32\lib\http\client.py", line 1392, in connect
    super().connect()
  File "C:\Users\raresteak\AppData\Local\Programs\Python\Python36-32\lib\http\client.py", line 936, in connect
    (self.host,self.port), self.timeout, self.source_address)
  File "C:\Users\raresteak\AppData\Local\Programs\Python\Python36-32\lib\socket.py", line 724, in create_connection
    raise err
  File "C:\Users\raresteak\AppData\Local\Programs\Python\Python36-32\lib\socket.py", line 713, in create_connection
    sock.connect(sa)
socket.timeout: timed out

During handling of the above exception, another exception occurred:

Traceback (most recent call last):
  File "F:\py\check_www_servers.py", line 14, in <module>
    CODE = urllib.request.urlopen(WWW,None,TIMEOUT).getcode()
  File "C:\Users\raresteak\AppData\Local\Programs\Python\Python36-32\lib\urllib\request.py", line 223, in urlopen
    return opener.open(url, data, timeout)
  File "C:\Users\raresteak\AppData\Local\Programs\Python\Python36-32\lib\urllib\request.py", line 526, in open
    response = self._open(req, data)
  File "C:\Users\raresteak\AppData\Local\Programs\Python\Python36-32\lib\urllib\request.py", line 544, in _open
    '_open', req)
  File "C:\Users\raresteak\AppData\Local\Programs\Python\Python36-32\lib\urllib\request.py", line 504, in _call_chain
    result = func(*args)
  File "C:\Users\raresteak\AppData\Local\Programs\Python\Python36-32\lib\urllib\request.py", line 1361, in https_open
    context=self._context, check_hostname=self._check_hostname)
  File "C:\Users\raresteak\AppData\Local\Programs\Python\Python36-32\lib\urllib\request.py", line 1320, in do_open
    raise URLError(err)
urllib.error.URLError: <urlopen error timed out>
```
I love try/except!!
